
[2024-05-19 20:45:34,189][dinov2][INFO] - using MLP layer as FFN
Using cache found in /Users/loris/.cache/torch/hub/facebookresearch_dinov2_main
/Users/loris/.cache/torch/hub/facebookresearch_dinov2_main/dinov2/layers/swiglu_ffn.py:51: UserWarning: xFormers is not available (SwiGLU)
  warnings.warn("xFormers is not available (SwiGLU)")
/Users/loris/.cache/torch/hub/facebookresearch_dinov2_main/dinov2/layers/attention.py:33: UserWarning: xFormers is not available (Attention)
  warnings.warn("xFormers is not available (Attention)")
/Users/loris/.cache/torch/hub/facebookresearch_dinov2_main/dinov2/layers/block.py:40: UserWarning: xFormers is not available (Block)
  warnings.warn("xFormers is not available (Block)")
Error executing job with overrides: []
Traceback (most recent call last):
  File "/Library/Frameworks/Python.framework/Versions/3.12/lib/python3.12/site-packages/hydra/_internal/utils.py", line 635, in _locate
    obj = import_module(part0)
          ^^^^^^^^^^^^^^^^^^^^
  File "/Library/Frameworks/Python.framework/Versions/3.12/lib/python3.12/importlib/__init__.py", line 90, in import_module
    return _bootstrap._gcd_import(name[level:], package, level)
           ^^^^^^^^^^^^^^^^^^^^^^^^^^^^^^^^^^^^^^^^^^^^^^^^^^^^
  File "<frozen importlib._bootstrap>", line 1387, in _gcd_import
  File "<frozen importlib._bootstrap>", line 1360, in _find_and_load
  File "<frozen importlib._bootstrap>", line 1324, in _find_and_load_unlocked
ModuleNotFoundError: No module named 'v2'
The above exception was the direct cause of the following exception:
Traceback (most recent call last):
  File "/Library/Frameworks/Python.framework/Versions/3.12/lib/python3.12/site-packages/hydra/_internal/instantiate/_instantiate2.py", line 134, in _resolve_target
    target = _locate(target)
             ^^^^^^^^^^^^^^^
  File "/Library/Frameworks/Python.framework/Versions/3.12/lib/python3.12/site-packages/hydra/_internal/utils.py", line 637, in _locate
    raise ImportError(
ImportError: Error loading 'v2.RandomHorizontalFlip':
ModuleNotFoundError("No module named 'v2'")
Are you sure that module 'v2' is installed?
The above exception was the direct cause of the following exception:
Traceback (most recent call last):
  File "/Users/loris/X/MODAL/Challenge/challenge-modal/train.py", line 97, in <module>
    train()
  File "/Library/Frameworks/Python.framework/Versions/3.12/lib/python3.12/site-packages/hydra/main.py", line 94, in decorated_main
    _run_hydra(
  File "/Library/Frameworks/Python.framework/Versions/3.12/lib/python3.12/site-packages/hydra/_internal/utils.py", line 394, in _run_hydra
    _run_app(
  File "/Library/Frameworks/Python.framework/Versions/3.12/lib/python3.12/site-packages/hydra/_internal/utils.py", line 457, in _run_app
    run_and_report(
  File "/Library/Frameworks/Python.framework/Versions/3.12/lib/python3.12/site-packages/hydra/_internal/utils.py", line 223, in run_and_report
    raise ex
  File "/Library/Frameworks/Python.framework/Versions/3.12/lib/python3.12/site-packages/hydra/_internal/utils.py", line 220, in run_and_report
    return func()
           ^^^^^^
  File "/Library/Frameworks/Python.framework/Versions/3.12/lib/python3.12/site-packages/hydra/_internal/utils.py", line 458, in <lambda>
    lambda: hydra.run(
            ^^^^^^^^^^
  File "/Library/Frameworks/Python.framework/Versions/3.12/lib/python3.12/site-packages/hydra/_internal/hydra.py", line 132, in run
    _ = ret.return_value
        ^^^^^^^^^^^^^^^^
  File "/Library/Frameworks/Python.framework/Versions/3.12/lib/python3.12/site-packages/hydra/core/utils.py", line 260, in return_value
    raise self._return_value
  File "/Library/Frameworks/Python.framework/Versions/3.12/lib/python3.12/site-packages/hydra/core/utils.py", line 186, in run_job
    ret.return_value = task_function(task_cfg)
                       ^^^^^^^^^^^^^^^^^^^^^^^
  File "/Users/loris/X/MODAL/Challenge/challenge-modal/train.py", line 15, in train
    datamodule = hydra.utils.instantiate(cfg.datamodule) #objet de classe DataModule avec tous les param√®tres de config
                 ^^^^^^^^^^^^^^^^^^^^^^^^^^^^^^^^^^^^^^^
  File "/Library/Frameworks/Python.framework/Versions/3.12/lib/python3.12/site-packages/hydra/_internal/instantiate/_instantiate2.py", line 226, in instantiate
    return instantiate_node(
           ^^^^^^^^^^^^^^^^^
  File "/Library/Frameworks/Python.framework/Versions/3.12/lib/python3.12/site-packages/hydra/_internal/instantiate/_instantiate2.py", line 342, in instantiate_node
    value = instantiate_node(
            ^^^^^^^^^^^^^^^^^
  File "/Library/Frameworks/Python.framework/Versions/3.12/lib/python3.12/site-packages/hydra/_internal/instantiate/_instantiate2.py", line 342, in instantiate_node
    value = instantiate_node(
            ^^^^^^^^^^^^^^^^^
  File "/Library/Frameworks/Python.framework/Versions/3.12/lib/python3.12/site-packages/hydra/_internal/instantiate/_instantiate2.py", line 317, in instantiate_node
    instantiate_node(item, convert=convert, recursive=recursive)
  File "/Library/Frameworks/Python.framework/Versions/3.12/lib/python3.12/site-packages/hydra/_internal/instantiate/_instantiate2.py", line 333, in instantiate_node
    _target_ = _resolve_target(node.get(_Keys.TARGET), full_key)
               ^^^^^^^^^^^^^^^^^^^^^^^^^^^^^^^^^^^^^^^^^^^^^^^^^
  File "/Library/Frameworks/Python.framework/Versions/3.12/lib/python3.12/site-packages/hydra/_internal/instantiate/_instantiate2.py", line 139, in _resolve_target
    raise InstantiationException(msg) from e
hydra.errors.InstantiationException: Error locating target 'v2.RandomHorizontalFlip', set env var HYDRA_FULL_ERROR=1 to see chained exception.
full_key: datamodule.train_transform3.transforms2