Using cache found in /Users/loris/.cache/torch/hub/facebookresearch_dinov2_main
/Users/loris/.cache/torch/hub/facebookresearch_dinov2_main/dinov2/layers/swiglu_ffn.py:51: UserWarning: xFormers is not available (SwiGLU)
  warnings.warn("xFormers is not available (SwiGLU)")
/Users/loris/.cache/torch/hub/facebookresearch_dinov2_main/dinov2/layers/attention.py:33: UserWarning: xFormers is not available (Attention)
  warnings.warn("xFormers is not available (Attention)")
/Users/loris/.cache/torch/hub/facebookresearch_dinov2_main/dinov2/layers/block.py:40: UserWarning: xFormers is not available (Block)
  warnings.warn("xFormers is not available (Block)")
[2024-05-10 14:40:48,373][dinov2][INFO] - using MLP layer as FFN
Error executing job with overrides: []
Traceback (most recent call last):
  File "/Users/loris/miniconda3/envs/cheese_challenge/lib/python3.10/site-packages/hydra/_internal/utils.py", line 644, in _locate
    obj = getattr(obj, part)
AttributeError: module 'data' has no attribute 'datamodule'
During handling of the above exception, another exception occurred:
Traceback (most recent call last):
  File "/Users/loris/miniconda3/envs/cheese_challenge/lib/python3.10/site-packages/hydra/_internal/utils.py", line 650, in _locate
    obj = import_module(mod)
  File "/Users/loris/miniconda3/envs/cheese_challenge/lib/python3.10/importlib/__init__.py", line 126, in import_module
    return _bootstrap._gcd_import(name[level:], package, level)
  File "<frozen importlib._bootstrap>", line 1050, in _gcd_import
  File "<frozen importlib._bootstrap>", line 1027, in _find_and_load
  File "<frozen importlib._bootstrap>", line 1006, in _find_and_load_unlocked
  File "<frozen importlib._bootstrap>", line 688, in _load_unlocked
  File "<frozen importlib._bootstrap_external>", line 883, in exec_module
  File "<frozen importlib._bootstrap>", line 241, in _call_with_frames_removed
  File "/Users/loris/X/MODAL/Challenge/challenge-modal/data/datamodule.py", line 2, in <module>
    from torchvision.datasets import ImageFolder
ModuleNotFoundError: No module named 'torchvision'
The above exception was the direct cause of the following exception:
Traceback (most recent call last):
  File "/Users/loris/miniconda3/envs/cheese_challenge/lib/python3.10/site-packages/hydra/_internal/instantiate/_instantiate2.py", line 134, in _resolve_target
    target = _locate(target)
  File "/Users/loris/miniconda3/envs/cheese_challenge/lib/python3.10/site-packages/hydra/_internal/utils.py", line 653, in _locate
    raise ImportError(
ImportError: Error loading 'data.datamodule.DataModule':
ModuleNotFoundError("No module named 'torchvision'")
Are you sure that 'datamodule' is importable from module 'data'?
The above exception was the direct cause of the following exception:
Traceback (most recent call last):
  File "/Users/loris/X/MODAL/Challenge/challenge-modal/train.py", line 93, in <module>
    train()
  File "/Users/loris/miniconda3/envs/cheese_challenge/lib/python3.10/site-packages/hydra/main.py", line 94, in decorated_main
    _run_hydra(
  File "/Users/loris/miniconda3/envs/cheese_challenge/lib/python3.10/site-packages/hydra/_internal/utils.py", line 394, in _run_hydra
    _run_app(
  File "/Users/loris/miniconda3/envs/cheese_challenge/lib/python3.10/site-packages/hydra/_internal/utils.py", line 457, in _run_app
    run_and_report(
  File "/Users/loris/miniconda3/envs/cheese_challenge/lib/python3.10/site-packages/hydra/_internal/utils.py", line 223, in run_and_report
    raise ex
  File "/Users/loris/miniconda3/envs/cheese_challenge/lib/python3.10/site-packages/hydra/_internal/utils.py", line 220, in run_and_report
    return func()
  File "/Users/loris/miniconda3/envs/cheese_challenge/lib/python3.10/site-packages/hydra/_internal/utils.py", line 458, in <lambda>
    lambda: hydra.run(
  File "/Users/loris/miniconda3/envs/cheese_challenge/lib/python3.10/site-packages/hydra/_internal/hydra.py", line 132, in run
    _ = ret.return_value
  File "/Users/loris/miniconda3/envs/cheese_challenge/lib/python3.10/site-packages/hydra/core/utils.py", line 260, in return_value
    raise self._return_value
  File "/Users/loris/miniconda3/envs/cheese_challenge/lib/python3.10/site-packages/hydra/core/utils.py", line 186, in run_job
    ret.return_value = task_function(task_cfg)
  File "/Users/loris/X/MODAL/Challenge/challenge-modal/train.py", line 15, in train
    datamodule = hydra.utils.instantiate(cfg.datamodule)
  File "/Users/loris/miniconda3/envs/cheese_challenge/lib/python3.10/site-packages/hydra/_internal/instantiate/_instantiate2.py", line 226, in instantiate
    return instantiate_node(
  File "/Users/loris/miniconda3/envs/cheese_challenge/lib/python3.10/site-packages/hydra/_internal/instantiate/_instantiate2.py", line 333, in instantiate_node
    _target_ = _resolve_target(node.get(_Keys.TARGET), full_key)
  File "/Users/loris/miniconda3/envs/cheese_challenge/lib/python3.10/site-packages/hydra/_internal/instantiate/_instantiate2.py", line 139, in _resolve_target
    raise InstantiationException(msg) from e
hydra.errors.InstantiationException: Error locating target 'data.datamodule.DataModule', set env var HYDRA_FULL_ERROR=1 to see chained exception.
full_key: datamodule